Workbook
Name W_AW: 'Metodologi Skor'!$C$5
Name W_CV: 'Metodologi Skor'!$C$6
Name W_SH: 'Metodologi Skor'!$C$7
Name W_GAYA_WOW: 'Ringkasan Gaya'!$C$15
Name W_GAYA_MEREK: 'Ringkasan Gaya'!$C$16
Name W_GAYA_MUDAH: 'Ringkasan Gaya'!$C$17

Sheet Ringkasan
A1: Rancangan Iklan & Video Privasimu: Q4 2026 → PP 33 berlaku (16 Jan 2027)
A2: Isi: 1 flow unggulan "semua modul" (± 3 menit, dengan versi 60 & 30 dtk) · 22 video modul · 32 video pendek 5/10/15 dtk · 48 konsep iklan meme · 253 gaya motion graphic (7 keluarga) · 33 frasa hook. Setiap video punya hook (reverse psychology / relate / anomali / logika dipatahkan) dan lokasi screenshot per adegan. Dibuat 29 Sep 2026, diperbarui 30 Sep 2026. Yang sudah jadi video: N01–N11, M01, M02, A22, T01–T03, GB05 (lihat kolom Status di Katalog Gaya).
A4: Sheet | B4: Isi
A5: Ringkasan Gaya | B5: Peta 253 gaya motion graphic dalam 7 keluarga: jumlah per status, bobot skor, cara membaca, dan 10 teratas tipografi & grafis-bentuk.
A6: Katalog Gaya | B6: Daftar lengkap gaya: tampilan, status, skor, video usulan (hook, alur, komposisi edukasi vs meme), modul, aset layar, teknik, catatan.
A7: Hook Frasa Viral | B7: 33 frasa pemancing (politik, warganet, kantor, suara meme) + aturan pakai aman dan tingkat risikonya.
A8: Flow Semua Modul | B8: Flow unggulan "Perjalanan Satu Data": semua modul dalam satu video (± 3 menit), per adegan + screenshot. Kolom terakhir menandai adegan untuk versi 60 & 30 dtk.
A9: Daftar Video Modul | B9: Ringkasan 22 video modul: judul, hook & jenisnya, target, pesan, CTA, dasar klaim, status screenshot.
A10: Flow per Modul | B10: Flow adegan per video modul: waktu, visual, path screenshot, crop/sorot/blur, teks layar, VO, SFX.
A11: Video Pendek 5-10-15 | B11: 32 video pendek (bumper 5 dtk, 10 dtk, 15 dtk), meme & serius.
A12: Rancangan Ads Meme | B12: 48 konsep iklan meme dengan skor Awareness · Convert · Share (bobot bisa diubah).
A13: Screenshot per Modul | B13: Inventaris screenshot: path, isi, status, catatan blur; daftar screenshot yang perlu diambil baru.
A14: Bank Sound Meme | B14: Hasil cek myinstants + versi aman tiap suara (synth / rekaman tim).
A15: Efek VO | B15: Preset efek suara VO (berat, tupai, telepon, toa, robot, gema, bisik, dll.).
... A18: Metodologi Skor | B18: Bobot skor, kriteria, 4 jenis hook, KPI validasi.
A20: Urutan produksi yang disarankan
A21: 1. Flow unggulan "Perjalanan Satu Data" (3 menit) + potongan 60 & 30 dtk: fondasi kampanye.
A22: 2. Video modul 10 produk inti di landing page: M02 GAP, M04 RoPA, M05 DPIA, M07 DSR, M08 Consent & Cookie, M13 Pihak Ketiga, M14 Transfer Lintas Negara, M11 Insiden, M15 Data Discovery, M19 Priva AI.
A23: 3. Video pendek dari potongan N11 & modul (P01–P32) untuk ritme harian.
A24: 4. Modul lain (M01, M03, M06, M09, M10, M12, M16–M18, M20–M22), dengan mengambil screenshot baru dulu bila statusnya "PERLU SCREENSHOT BARU".
A26: Catatan penting
A27: • Screenshot yang dirujuk adalah tampilan frontend LAMA (sesuai arahan: boleh dipakai). Path relatif dari D:\AI\privasimu.
A28: • JANGAN pakai: dataroom/02-superadmin/holding-dashboard/* (nama perusahaan nyata), dsr/01-overview (merek bank nyata), tabel cookie (nama layanan & domain nyata), data-discovery/03-system-detail (form kredensial), bagian "DPO / Team" di ropa/03 (email).
A29: • myinstants.com: hanya untuk pemakaian pribadi & nonkomersial → file aslinya tidak dipakai. "FAAAH" dkk. direkam ulang tim atau dibuat dengan ElevenLabs (paket berbayar).
A30: • Suara TTS sekarang (edge-tts) hanya placeholder. Untuk logat Indonesia natural: ElevenLabs, Prosa.ai, atau Google Chirp 3 HD (sheet Opsi TTS).
A31: • Klaim produk mengacu fakta_produk.json, katalog modul, dan tampilan aplikasi (kolom "Dasar fakta"). Tokoh (mis. Rina) & angka lucu adalah ilustrasi. Promo "Start Pre Check (gratis)" & "konsultasi gratis": cek masih berlaku.
A33: Top 10 konsep meme (skor total, bobot awal 35/35/30)
A34: # | B34: ID | C34: Judul | D34: Jenis hook | E34: Skor | F34: Status
A35: 1 | B35: A22 | C35: Rekap Tahunan DPO 2026 | D35: Relate | E35: 8.2 | F35: Baru
A36: 2 | B36: A47 | C36: Roasting RoPA (live) | D36: Reverse psychology | E36: 8 | F36: Baru
A37: 3 | B37: A48 | C37: #RoPA60Detik challenge | D37: Reverse psychology | E37: 8 | F37: Baru
A38: 4 | B38: A02 | C38: Astaga, bercanda (Pak Bos edition) | D38: Relate | E38: 7.9 | F38: Sudah jadi (potongan N11)
A39: 5 | B39: A09 | C39: Nobody: / Marketing jam 5 sore | D39: Relate | E39: 7.9 | F39: Baru (kit, mirip N05)
A40: 6 | B40: A01 | C40: FAAAH: RoPA-nya masih Excel | D40: Relate | E40: 7.7 | F40: Bisa dibuat dari kit (varian N04)
A41: 7 | B41: A04 | C41: Orang have vs haven't vs not yet | D41: Relate | E41: 7.7 | F41: Sudah jadi (potongan N11)
A42: 8 | B42: A08 | C42: EMOTIONAL DAMAGE: denda 2% | D42: Anomali | E42: 7.7 | F42: Baru (kit)
A43: 9 | B43: A21 | C43: Day in the life of a DPO (versi jujur) | D43: Relate | E43: 7.7 | F43: Baru
A44: 10 | B44: A24 | C44: Resolusi 2027: patuh PP 33 | D44: Logika dipatahkan | E44: 7.7 | F44: Baru

Sheet Ringkasan Gaya
A1: Peta gaya motion graphic: 7 keluarga
A2: 253 gaya, masing-masing dengan usulan video (hook, alur, modul, komposisi edukasi vs meme). Urutan produksi: one-line art dulu (permintaan), lalu SEMUA tipografi, lalu SEMUA grafis & bentuk, baru keluarga lain. Daftar lengkap di sheet "Katalog Gaya" (saring kolom Keluarga, urutkan kolom Peringkat).
A4: Kode | B4: Keluarga | C4: Ciri | D4: Gelombang | E4: Jumlah gaya | F4: Sudah dipakai | G4: Bisa | H4: Berat | I4: Tidak cocok | J4: Rata-rata wow
A5: TY | B5: Tipografi | C5: Huruf jadi bintang utama; hampir tanpa gambar. | D5: 1 | E5: =COUNTIF('Katalog Gaya'!$B$2:$B$254,B5) | F5: =COUNTIFS('Katalog Gaya'!$B$2:$B$254,$B5,'Katalog Gaya'!$E$2:$E$254,"Sudah") | G5: =COUNTIFS('Katalog Gaya'!$B$2:$B$254,$B5,'Katalog Gaya'!$E$2:$E$254,"Bisa") | H5: =COUNTIFS('Katalog Gaya'!$B$2:$B$254,$B5,'Katalog Gaya'!$E$2:$E$254,"Berat") | I5: =COUNTIFS('Katalog Gaya'!$B$2:$B$254,$B5,'Katalog Gaya'!$E$2:$E$254,"Tidak cocok") | J5: =ROUND(AVERAGEIF('Katalog Gaya'!$B$2:$B$254,B5,'Katalog Gaya'!$H$2:$H$254),1)
A6: GB | B6: Grafis & bentuk | C6: Bentuk, garis, dan diagram yang bercerita. | D6: 2 | E6: =COUNTIF('Katalog Gaya'!$B$2:$B$254,B6) | F6: =COUNTIFS('Katalog Gaya'!$B$2:$B$254,$B6,'Katalog Gaya'!$E$2:$E$254,"Sudah") | G6: =COUNTIFS('Katalog Gaya'!$B$2:$B$254,$B6,'Katalog Gaya'!$E$2:$E$254,"Bisa") | H6: =COUNTIFS('Katalog Gaya'!$B$2:$B$254,$B6,'Katalog Gaya'!$E$2:$E$254,"Berat") | I6: =COUNTIFS('Katalog Gaya'!$B$2:$B$254,$B6,'Katalog Gaya'!$E$2:$E$254,"Tidak cocok") | J6: =ROUND(AVERAGEIF('Katalog Gaya'!$B$2:$B$254,B6,'Katalog Gaya'!$H$2:$H$254),1)
A7: CR | B7: Craft (buatan tangan) | C7: Tekstur kertas, tinta, dan benda nyata. | D7: 3 | E7: =COUNTIF('Katalog Gaya'!$B$2:$B$254,B7) | F7: =COUNTIFS('Katalog Gaya'!$B$2:$B$254,$B7,'Katalog Gaya'!$E$2:$E$254,"Sudah") | G7: =COUNTIFS('Katalog Gaya'!$B$2:$B$254,$B7,'Katalog Gaya'!$E$2:$E$254,"Bisa") | H7: =COUNTIFS('Katalog Gaya'!$B$2:$B$254,$B7,'Katalog Gaya'!$E$2:$E$254,"Berat") | I7: =COUNTIFS('Katalog Gaya'!$B$2:$B$254,$B7,'Katalog Gaya'!$E$2:$E$254,"Tidak cocok") | J7: =ROUND(AVERAGEIF('Katalog Gaya'!$B$2:$B$254,B7,'Katalog Gaya'!$H$2:$H$254),1)
A8: UI | B8: Layar & UI | C8: Cerita terjadi di layar: aplikasi, chat, desktop. | D8: 4 | E8: =COUNTIF('Katalog Gaya'!$B$2:$B$254,B8) | F8: =COUNTIFS('Katalog Gaya'!$B$2:$B$254,$B8,'Katalog Gaya'!$E$2:$E$254,"Sudah") | G8: =COUNTIFS('Katalog Gaya'!$B$2:$B$254,$B8,'Katalog Gaya'!$E$2:$E$254,"Bisa") | H8: =COUNTIFS('Katalog Gaya'!$B$2:$B$254,$B8,'Katalog Gaya'!$E$2:$E$254,"Berat") | I8: =COUNTIFS('Katalog Gaya'!$B$2:$B$254,$B8,'Katalog Gaya'!$E$2:$E$254,"Tidak cocok") | J8: =ROUND(AVERAGEIF('Katalog Gaya'!$B$2:$B$254,B8,'Katalog Gaya'!$H$2:$H$254),1)
A9: SN | B9: Sinematik & retro | C9: Suasana film, cahaya, dan nostalgia. | D9: 5 | E9: =COUNTIF('Katalog Gaya'!$B$2:$B$254,B9) | F9: =COUNTIFS('Katalog Gaya'!$B$2:$B$254,$B9,'Katalog Gaya'!$E$2:$E$254,"Sudah") | G9: =COUNTIFS('Katalog Gaya'!$B$2:$B$254,$B9,'Katalog Gaya'!$E$2:$E$254,"Bisa") | H9: =COUNTIFS('Katalog Gaya'!$B$2:$B$254,$B9,'Katalog Gaya'!$E$2:$E$254,"Berat") | I9: =COUNTIFS('Katalog Gaya'!$B$2:$B$254,$B9,'Katalog Gaya'!$E$2:$E$254,"Tidak cocok") | J9: =ROUND(AVERAGEIF('Katalog Gaya'!$B$2:$B$254,B9,'Katalog Gaya'!$H$2:$H$254),1)
A10: PF | B10: Parodi format | C10: Format sehari-hari yang dipelesetkan. | D10: 6 | E10: =COUNTIF('Katalog Gaya'!$B$2:$B$254,B10) | F10: =COUNTIFS('Katalog Gaya'!$B$2:$B$254,$B10,'Katalog Gaya'!$E$2:$E$254,"Sudah") | G10: =COUNTIFS('Katalog Gaya'!$B$2:$B$254,$B10,'Katalog Gaya'!$E$2:$E$254,"Bisa") | H10: =COUNTIFS('Katalog Gaya'!$B$2:$B$254,$B10,'Katalog Gaya'!$E$2:$E$254,"Berat") | I10: =COUNTIFS('Katalog Gaya'!$B$2:$B$254,$B10,'Katalog Gaya'!$E$2:$E$254,"Tidak cocok") | J10: =ROUND(AVERAGEIF('Katalog Gaya'!$B$2:$B$254,B10,'Katalog Gaya'!$H$2:$H$254),1)
A11: SE | B11: Struktur edit | C11: Cara menyusun cerita; bisa digabung dengan gaya mana pun. | D11: 7 | E11: =COUNTIF('Katalog Gaya'!$B$2:$B$254,B11) | F11: =COUNTIFS('Katalog Gaya'!$B$2:$B$254,$B11,'Katalog Gaya'!$E$2:$E$254,"Sudah") | G11: =COUNTIFS('Katalog Gaya'!$B$2:$B$254,$B11,'Katalog Gaya'!$E$2:$E$254,"Bisa") | H11: =COUNTIFS('Katalog Gaya'!$B$2:$B$254,$B11,'Katalog Gaya'!$E$2:$E$254,"Berat") | I11: =COUNTIFS('Katalog Gaya'!$B$2:$B$254,$B11,'Katalog Gaya'!$E$2:$E$254,"Tidak cocok") | J11: =ROUND(AVERAGEIF('Katalog Gaya'!$B$2:$B$254,B11,'Katalog Gaya'!$H$2:$H$254),1)
B12: TOTAL | E12: =SUM(E5:E11) | F12: =SUM(F5:F11) | G12: =SUM(G5:G11) | H12: =SUM(H5:H11) | I12: =SUM(I5:I11) | J12: =ROUND(AVERAGE('Katalog Gaya'!$H$2:$H$254),1)
A14: Bobot skor prioritas (ubah angka di kolom C; skor & peringkat di "Katalog Gaya" ikut berubah)
B15: Wow (daya tarik visual) | C15: 0.45 | D15: Seberapa kuat gaya ini menghentikan scroll.
B16: Cocok merek | C16: 0.35 | D16: Seberapa pas untuk merek B2B yang serius.
B17: Mudah dibuat | C17: 0.2 | D17: Dari kolom Upaya: upaya 1 = nilai 9, upaya 5 = nilai 1 (rumus 11 − 2 × upaya).
B18: Total bobot | C18: =SUM(C15:C17)
A20: Cara membaca
B21: Status | C21: Sudah = sudah dipakai di video yang ada · Bisa = bisa dibuat dengan mesin sekarang · Berat = bisa, tapi butuh waktu/aset lebih · Tidak cocok = butuh footage asli, 3D, ilustrator, atau izin.
B22: Upaya | C22: 1 = beberapa jam kerja · 3 = sekelas video T01–T03 · 5 = paling berat (banyak objek atau 3D semu).
B23: Komposisi | C23: Porsi durasi untuk hiburan/format meme vs penjelasan & bukti produk. Ubah kolom "Meme %"; kolom Edukasi & Komposisi mengikuti. 0% = murni edukasi, 100% = full meme.
B24: Gelombang | C24: 0 = dikerjakan pertama (one-line art) · 1 = tipografi · 2 = grafis & bentuk · 3–7 = keluarga lain. Di dalam satu gelombang, ikuti kolom Peringkat.
B25: Skor | C25: Skor wow, cocok merek, dan upaya adalah ESTIMASI EDITORIAL, bukan data. Validasi dengan uji tayang.
B26: Aturan isi | C26: Fitur hanya dari fakta_produk.json/screenshot asli · angka di hook yang bukan fakta = ilustrasi (diberi label) · "pihak ketiga", bukan "vendor" · tanpa wajah/suara/nama tokoh nyata dan tanpa merek pihak lain.
A28: Urutan produksi: 10 teratas tiap gelombang prioritas (mengikuti skor; berubah otomatis bila bobot/skor diubah)
A29: # | B29: Tipografi: gaya | C29: Video usulan | D29: Komposisi | E29: Skor | F29: # | G29: Grafis & bentuk: gaya | H29: Video usulan | I29: Komposisi | J29: Skor
A30: 1 | B30: =IFERROR(INDEX('Katalog Gaya'!$C$2:$C$254,MATCH("Tipografi|"&1,'Katalog Gaya'!$AB$2:$AB$254,0)),"") | C30: =IFERROR(INDEX('Katalog Gaya'!$M$2:$M$254,MATCH("Tipografi|"&1,'Katalog Gaya'!$AB$2:$AB$254,0)),"") | D30: =IFERROR(INDEX('Katalog Gaya'!$S$2:$S$254,MATCH("Tipografi|"&1,'Katalog Gaya'!$AB$2:$AB$254,0)),"") | E30: =IFERROR(INDEX('Katalog Gaya'!$J$2:$J$254,MATCH("Tipografi|"&1,'Katalog Gaya'!$AB$2:$AB$254,0)),"") | F30: 1 | G30: =IFERROR(INDEX('Katalog Gaya'!$C$2:$C$254,MATCH("Grafis & bentuk|"&1,'Katalog Gaya'!$AB$2:$AB$254,0)),"") | H30: =IFERROR(INDEX('Katalog Gaya'!$M$2:$M$254,MATCH("Grafis & bentuk|"&1,'Katalog Gaya'!$AB$2:$AB$254,0)),"") | I30: =IFERROR(INDEX('Katalog Gaya'!$S$2:$S$254,MATCH("Grafis & bentuk|"&1,'Katalog Gaya'!$AB$2:$AB$254,0)),"") | J30: =IFERROR(INDEX('Katalog Gaya'!$J$2:$J$254,MATCH("Grafis & bentuk|"&1,'Katalog Gaya'!$AB$2:$AB$254,0)),"")
A31: 2 | B31: =IFERROR(INDEX('Katalog Gaya'!$C$2:$C$254,MATCH("Tipografi|"&2,'Katalog Gaya'!$AB$2:$AB$254,0)),"") | C31: =IFERROR(INDEX('Katalog Gaya'!$M$2:$M$254,MATCH("Tipografi|"&2,'Katalog Gaya'!$AB$2:$AB$254,0)),"") | D31: =IFERROR(INDEX('Katalog Gaya'!$S$2:$S$254,MATCH("Tipografi|"&2,'Katalog Gaya'!$AB$2:$AB$254,0)),"") | E31: =IFERROR(INDEX('Katalog Gaya'!$J$2:$J$254,MATCH("Tipografi|"&2,'Katalog Gaya'!$AB$2:$AB$254,0)),"") | F31: 2 | G31: =IFERROR(INDEX('Katalog Gaya'!$C$2:$C$254,MATCH("Grafis & bentuk|"&2,'Katalog Gaya'!$AB$2:$AB$254,0)),"") | H31: =IFERROR(INDEX('Katalog Gaya'!$M$2:$M$254,MATCH("Grafis & bentuk|"&2,'Katalog Gaya'!$AB$2:$AB$254,0)),"") | I31: =IFERROR(INDEX('Katalog Gaya'!$S$2:$S$254,MATCH("Grafis & bentuk|"&2,'Katalog Gaya'!$AB$2:$AB$254,0)),"") | J31: =IFERROR(INDEX('Katalog Gaya'!$J$2:$J$254,MATCH("Grafis & bentuk|"&2,'Katalog Gaya'!$AB$2:$AB$254,0)),"")
A32: 3 | B32: =IFERROR(INDEX('Katalog Gaya'!$C$2:$C$254,MATCH("Tipografi|"&3,'Katalog Gaya'!$AB$2:$AB$254,0)),"") | C32: =IFERROR(INDEX('Katalog Gaya'!$M$2:$M$254,MATCH("Tipografi|"&3,'Katalog Gaya'!$AB$2:$AB$254,0)),"") | D32: =IFERROR(INDEX('Katalog Gaya'!$S$2:$S$254,MATCH("Tipografi|"&3,'Katalog Gaya'!$AB$2:$AB$254,0)),"") | E32: =IFERROR(INDEX('Katalog Gaya'!$J$2:$J$254,MATCH("Tipografi|"&3,'Katalog Gaya'!$AB$2:$AB$254,0)),"") | F32: 3 | G32: =IFERROR(INDEX('Katalog Gaya'!$C$2:$C$254,MATCH("Grafis & bentuk|"&3,'Katalog Gaya'!$AB$2:$AB$254,0)),"") | H32: =IFERROR(INDEX('Katalog Gaya'!$M$2:$M$254,MATCH("Grafis & bentuk|"&3,'Katalog Gaya'!$AB$2:$AB$254,0)),"") | I32: =IFERROR(INDEX('Katalog Gaya'!$S$2:$S$254,MATCH("Grafis & bentuk|"&3,'Katalog Gaya'!$AB$2:$AB$254,0)),"") | J32: =IFERROR(INDEX('Katalog Gaya'!$J$2:$J$254,MATCH("Grafis & bentuk|"&3,'Katalog Gaya'!$AB$2:$AB$254,0)),"")
A33: 4 | B33: =IFERROR(INDEX('Katalog Gaya'!$C$2:$C$254,MATCH("Tipografi|"&4,'Katalog Gaya'!$AB$2:$AB$254,0)),"") | C33: =IFERROR(INDEX('Katalog Gaya'!$M$2:$M$254,MATCH("Tipografi|"&4,'Katalog Gaya'!$AB$2:$AB$254,0)),"") | D33: =IFERROR(INDEX('Katalog Gaya'!$S$2:$S$254,MATCH("Tipografi|"&4,'Katalog Gaya'!$AB$2:$AB$254,0)),"") | E33: =IFERROR(INDEX('Katalog Gaya'!$J$2:$J$254,MATCH("Tipografi|"&4,'Katalog Gaya'!$AB$2:$AB$254,0)),"") | F33: 4 | G33: =IFERROR(INDEX('Katalog Gaya'!$C$2:$C$254,MATCH("Grafis & bentuk|"&4,'Katalog Gaya'!$AB$2:$AB$254,0)),"") | H33: =IFERROR(INDEX('Katalog Gaya'!$M$2:$M$254,MATCH("Grafis & bentuk|"&4,'Katalog Gaya'!$AB$2:$AB$254,0)),"") | I33: =IFERROR(INDEX('Katalog Gaya'!$S$2:$S$254,MATCH("Grafis & bentuk|"&4,'Katalog Gaya'!$AB$2:$AB$254,0)),"") | J33: =IFERROR(INDEX('Katalog Gaya'!$J$2:$J$254,MATCH("Grafis & bentuk|"&4,'Katalog Gaya'!$AB$2:$AB$254,0)),"")
A34: 5 | B34: =IFERROR(INDEX('Katalog Gaya'!$C$2:$C$254,MATCH("Tipografi|"&5,'Katalog Gaya'!$AB$2:$AB$254,0)),"") | C34: =IFERROR(INDEX('Katalog Gaya'!$M$2:$M$254,MATCH("Tipografi|"&5,'Katalog Gaya'!$AB$2:$AB$254,0)),"") | D34: =IFERROR(INDEX('Katalog Gaya'!$S$2:$S$254,MATCH("Tipografi|"&5,'Katalog Gaya'!$AB$2:$AB$254,0)),"") | E34: =IFERROR(INDEX('Katalog Gaya'!$J$2:$J$254,MATCH("Tipografi|"&5,'Katalog Gaya'!$AB$2:$AB$254,0)),"") | F34: 5 | G34: =IFERROR(INDEX('Katalog Gaya'!$C$2:$C$254,MATCH("Grafis & bentuk|"&5,'Katalog Gaya'!$AB$2:$AB$254,0)),"") | H34: =IFERROR(INDEX('Katalog Gaya'!$M$2:$M$254,MATCH("Grafis & bentuk|"&5,'Katalog Gaya'!$AB$2:$AB$254,0)),"") | I34: =IFERROR(INDEX('Katalog Gaya'!$S$2:$S$254,MATCH("Grafis & bentuk|"&5,'Katalog Gaya'!$AB$2:$AB$254,0)),"") | J34: =IFERROR(INDEX('Katalog Gaya'!$J$2:$J$254,MATCH("Grafis & bentuk|"&5,'Katalog Gaya'!$AB$2:$AB$254,0)),"")
A35: 6 | B35: =IFERROR(INDEX('Katalog Gaya'!$C$2:$C$254,MATCH("Tipografi|"&6,'Katalog Gaya'!$AB$2:$AB$254,0)),"") | C35: =IFERROR(INDEX('Katalog Gaya'!$M$2:$M$254,MATCH("Tipografi|"&6,'Katalog Gaya'!$AB$2:$AB$254,0)),"") | D35: =IFERROR(INDEX('Katalog Gaya'!$S$2:$S$254,MATCH("Tipografi|"&6,'Katalog Gaya'!$AB$2:$AB$254,0)),"") | E35: =IFERROR(INDEX('Katalog Gaya'!$J$2:$J$254,MATCH("Tipografi|"&6,'Katalog Gaya'!$AB$2:$AB$254,0)),"") | F35: 6 | G35: =IFERROR(INDEX('Katalog Gaya'!$C$2:$C$254,MATCH("Grafis & bentuk|"&6,'Katalog Gaya'!$AB$2:$AB$254,0)),"") | H35: =IFERROR(INDEX('Katalog Gaya'!$M$2:$M$254,MATCH("Grafis & bentuk|"&6,'Katalog Gaya'!$AB$2:$AB$254,0)),"") | I35: =IFERROR(INDEX('Katalog Gaya'!$S$2:$S$254,MATCH("Grafis & bentuk|"&6,'Katalog Gaya'!$AB$2:$AB$254,0)),"") | J35: =IFERROR(INDEX('Katalog Gaya'!$J$2:$J$254,MATCH("Grafis & bentuk|"&6,'Katalog Gaya'!$AB$2:$AB$254,0)),"")
A36: 7 | B36: =IFERROR(INDEX('Katalog Gaya'!$C$2:$C$254,MATCH("Tipografi|"&7,'Katalog Gaya'!$AB$2:$AB$254,0)),"") | C36: =IFERROR(INDEX('Katalog Gaya'!$M$2:$M$254,MATCH("Tipografi|"&7,'Katalog Gaya'!$AB$2:$AB$254,0)),"") | D36: =IFERROR(INDEX('Katalog Gaya'!$S$2:$S$254,MATCH("Tipografi|"&7,'Katalog Gaya'!$AB$2:$AB$254,0)),"") | E36: =IFERROR(INDEX('Katalog Gaya'!$J$2:$J$254,MATCH("Tipografi|"&7,'Katalog Gaya'!$AB$2:$AB$254,0)),"") | F36: 7 | G36: =IFERROR(INDEX('Katalog Gaya'!$C$2:$C$254,MATCH("Grafis & bentuk|"&7,'Katalog Gaya'!$AB$2:$AB$254,0)),"") | H36: =IFERROR(INDEX('Katalog Gaya'!$M$2:$M$254,MATCH("Grafis & bentuk|"&7,'Katalog Gaya'!$AB$2:$AB$254,0)),"") | I36: =IFERROR(INDEX('Katalog Gaya'!$S$2:$S$254,MATCH("Grafis & bentuk|"&7,'Katalog Gaya'!$AB$2:$AB$254,0)),"") | J36: =IFERROR(INDEX('Katalog Gaya'!$J$2:$J$254,MATCH("Grafis & bentuk|"&7,'Katalog Gaya'!$AB$2:$AB$254,0)),"")
A37: 8 | B37: =IFERROR(INDEX('Katalog Gaya'!$C$2:$C$254,MATCH("Tipografi|"&8,'Katalog Gaya'!$AB$2:$AB$254,0)),"") | C37: =IFERROR(INDEX('Katalog Gaya'!$M$2:$M$254,MATCH("Tipografi|"&8,'Katalog Gaya'!$AB$2:$AB$254,0)),"") | D37: =IFERROR(INDEX('Katalog Gaya'!$S$2:$S$254,MATCH("Tipografi|"&8,'Katalog Gaya'!$AB$2:$AB$254,0)),"") | E37: =IFERROR(INDEX('Katalog Gaya'!$J$2:$J$254,MATCH("Tipografi|"&8,'Katalog Gaya'!$AB$2:$AB$254,0)),"") | F37: 8 | G37: =IFERROR(INDEX('Katalog Gaya'!$C$2:$C$254,MATCH("Grafis & bentuk|"&8,'Katalog Gaya'!$AB$2:$AB$254,0)),"") | H37: =IFERROR(INDEX('Katalog Gaya'!$M$2:$M$254,MATCH("Grafis & bentuk|"&8,'Katalog Gaya'!$AB$2:$AB$254,0)),"") | I37: =IFERROR(INDEX('Katalog Gaya'!$S$2:$S$254,MATCH("Grafis & bentuk|"&8,'Katalog Gaya'!$AB$2:$AB$254,0)),"") | J37: =IFERROR(INDEX('Katalog Gaya'!$J$2:$J$254,MATCH("Grafis & bentuk|"&8,'Katalog Gaya'!$AB$2:$AB$254,0)),"")
A38: 9 | B38: =IFERROR(INDEX('Katalog Gaya'!$C$2:$C$254,MATCH("Tipografi|"&9,'Katalog Gaya'!$AB$2:$AB$254,0)),"") | C38: =IFERROR(INDEX('Katalog Gaya'!$M$2:$M$254,MATCH("Tipografi|"&9,'Katalog Gaya'!$AB$2:$AB$254,0)),"") | D38: =IFERROR(INDEX('Katalog Gaya'!$S$2:$S$254,MATCH("Tipografi|"&9,'Katalog Gaya'!$AB$2:$AB$254,0)),"") | E38: =IFERROR(INDEX('Katalog Gaya'!$J$2:$J$254,MATCH("Tipografi|"&9,'Katalog Gaya'!$AB$2:$AB$254,0)),"") | F38: 9 | G38: =IFERROR(INDEX('Katalog Gaya'!$C$2:$C$254,MATCH("Grafis & bentuk|"&9,'Katalog Gaya'!$AB$2:$AB$254,0)),"") | H38: =IFERROR(INDEX('Katalog Gaya'!$M$2:$M$254,MATCH("Grafis & bentuk|"&9,'Katalog Gaya'!$AB$2:$AB$254,0)),"") | I38: =IFERROR(INDEX('Katalog Gaya'!$S$2:$S$254,MATCH("Grafis & bentuk|"&9,'Katalog Gaya'!$AB$2:$AB$254,0)),"") | J38: =IFERROR(INDEX('Katalog Gaya'!$J$2:$J$254,MATCH("Grafis & bentuk|"&9,'Katalog Gaya'!$AB$2:$AB$254,0)),"")
A39: 10 | B39: =IFERROR(INDEX('Katalog Gaya'!$C$2:$C$254,MATCH("Tipografi|"&10,'Katalog Gaya'!$AB$2:$AB$254,0)),"") | C39: =IFERROR(INDEX('Katalog Gaya'!$M$2:$M$254,MATCH("Tipografi|"&10,'Katalog Gaya'!$AB$2:$AB$254,0)),"") | D39: =IFERROR(INDEX('Katalog Gaya'!$S$2:$S$254,MATCH("Tipografi|"&10,'Katalog Gaya'!$AB$2:$AB$254,0)),"") | E39: =IFERROR(INDEX('Katalog Gaya'!$J$2:$J$254,MATCH("Tipografi|"&10,'Katalog Gaya'!$AB$2:$AB$254,0)),"") | F39: 10 | G39: =IFERROR(INDEX('Katalog Gaya'!$C$2:$C$254,MATCH("Grafis & bentuk|"&10,'Katalog Gaya'!$AB$2:$AB$254,0)),"") | H39: =IFERROR(INDEX('Katalog Gaya'!$M$2:$M$254,MATCH("Grafis & bentuk|"&10,'Katalog Gaya'!$AB$2:$AB$254,0)),"") | I39: =IFERROR(INDEX('Katalog Gaya'!$S$2:$S$254,MATCH("Grafis & bentuk|"&10,'Katalog Gaya'!$AB$2:$AB$254,0)),"") | J39: =IFERROR(INDEX('Katalog Gaya'!$J$2:$J$254,MATCH("Grafis & bentuk|"&10,'Katalog Gaya'!$AB$2:$AB$254,0)),"")
A41: Dikerjakan pertama: GB05 · One-line art (satu garis tanpa putus) · video “Satu Garis” (64 dtk) — sudah dirakit, tinggal render.

Sheet Katalog Gaya
A1: Kode | B1: Keluarga | C1: Gaya | D1: Tampilannya | E1: Status | F1: Dipakai di | G1: Upaya (1–5) | H1: Wow (1–10) | I1: Cocok merek (1–10) | J1: SKOR PRIORITAS | K1: Peringkat di keluarga | L1: Gelombang produksi | M1: Video usulan | N1: Jenis hook | O1: Hook (0–3 detik) | P1: Alur singkat | Q1: Meme % | R1: Edukasi % | S1: Komposisi | T1: Modul / fitur | U1: Aset layar (motion/assets/app) | V1: Durasi | W1: Sumber di plan | X1: Teknik (cara buat di mesin kita) | Y1: Catatan / risiko | Z1: siap | AA1: kunci skor | AB1: kunci peringkat
A2: TY01 | B2: Tipografi | C2: Kinetic typography (kamera menjelajah kanvas) | D2: Kata muncul tepat saat diucapkan; kamera geser-putar di satu kanvas besar, lalu mundur memperlihatkan semuanya. | E2: Sudah | F2: T02 | G2: 4 | H2: 8 | I2: 9 | J2: =IF(E2="Tidak cocok","",ROUND(H2*W_GAYA_WOW+I2*W_GAYA_MEREK+(11-2*G2)*W_GAYA_MUDAH,1)) | K2: =IF(Z2=1,COUNTIFS($B$2:$B$254,B2,$AA$2:$AA$254,">"&AA2)+1,"—") | L2: 1 | M2: Jangan Tonton Video Ini | N2: Reverse psychology | O2: “Jangan tonton video ini… kalau perusahaanmu tidak menyimpan satu pun data pelanggan.” | P2: Hook → PP 33 & sanksi 2% → “merasa aman” dicoret → RoPA, DPIA, DSR, insiden → kanvas utuh → CTA | Q2: 0.1 | R2: =IF(Q2="","",1-Q2) | S2: =IF(Q2="","—",TEXT(1-Q2,"0%")&" edukasi · "&TEXT(Q2,"0%")&" meme") | T2: Platform | U2: — | V2: 53,6 dtk | W2: T02 (sudah dirender) | X2: Blok teks di kanvas dunia; kamera per baris dari waktu VO; font variabel Archivo + Instrument Serif. | Z2: =IF(OR(E2="Bisa",E2="Berat"),1,0) | AA2: =IF(Z2=1,J2-ROW()/100000,"") | AB2: =B2&"|"&K2
A3: TY02 | B3: Tipografi | C3: Stomp / beat-cut | D3: Kata raksasa menghentak di tiap ketukan stomp-stomp-clap; warna blok berganti keras. | E3: Sudah | F3: T01 | G3: 4 | H3: 9 | I3: 8 | J3: =IF(E3="Tidak cocok","",ROUND(H3*W_GAYA_WOW+I3*W_GAYA_MEREK+(11-2*G3)*W_GAYA_MUDAH,1)) | K3: =IF(Z3=1,COUNTIFS($B$2:$B$254,B3,$AA$2:$AA$254,">"&AA3)+1,"—") | L3: 1 | M3: Satu Platform | N3: Anomali | O3: “12 spreadsheet. 7 folder. 3 grup chat. 1 DPO.” | P3: Hook → “Cukup. Saatnya rapi.” → 8 modul menghentak + screenshot asli → PP 33 → “Siap?” → CTA | Q3: 0.2 | R3: =IF(Q3="","",1-Q3) | S3: =IF(Q3="","—",TEXT(1-Q3,"0%")&" edukasi · "&TEXT(Q3,"0%")&" meme") | T3: Platform | U3: ropa-list-baru, dpia-risiko, dsr-detail, consent-detail, breach-detail, gap-hasil, ai-agent-chat, dpo-academy | V3: 38,2 dtk | W3: T01 (sudah dirender) | X3: Kartu per ketukan (durasi scene kelipatan birama), kilat di tiap clap, musik stomp disintesis. | Y3: Angka hook = hiperbola. | Z3: =IF(OR(E3="Bisa",E3="Berat"),1,0) | AA3: =IF(Z3=1,J3-ROW()/100000,"") | AB3: =B3&"|"&K3
A4: TY03 | B4: Tipografi | C4: Split-flap (papan jadwal bandara) | D4: Huruf dan angka berputar seperti papan keberangkatan lama. | E4: Sudah | F4: N01 | G4: 3 | H4: 8 | I4: 9 | J4: =IF(E4="Tidak cocok","",ROUND(H4*W_GAYA_WOW+I4*W_GAYA_MEREK+(11-2*G4)*W_GAYA_MUDAH,1)) | K4: =IF(Z4=1,COUNTIFS($B$2:$B$254,B4,$AA$2:$AA$254,">"&AA4)+1,"—") | L4: 1 | M4: Hitung mundur PP 33/2026 | N4: Anomali | O4: Papan berputar menuju “16.01.2027”. | P4: Hitung mundur → kewajiban → program siap PP 33 → CTA | Q4: 0.1 | R4: =IF(Q4="","",1-Q4) | S4: =IF(Q4="","—",TEXT(1-Q4,"0%")&" edukasi · "&TEXT(Q4,"0%")&" meme") | T4: Program siap PP 33 | U4: — | V4: 45 dtk | W4: N01 (sudah dirender) | X4: Kartu huruf rotateX dua belahan; bunyi flip per huruf. | Z4: =IF(OR(E4="Bisa",E4="Berat"),1,0) | AA4: =IF(Z4=1,J4-ROW()/100000,"") | AB4: =B4&"|"&K4
A5: TY04 | B5: Tipografi | C5: Huruf guntingan + stempel (stop motion) | D5: Huruf potongan majalah ditempel satu-satu di papan gabus, stempel nilai dijatuhkan; gerak patah-patah 12 fps. | E5: Sudah | F5: T03 | G5: 4 | H5: 9 | I5: 7 | J5: =IF(E5="Tidak cocok","",ROUND(H5*W_GAYA_WOW+I5*W_GAYA_MEREK+(11-2*G5)*W_GAYA_MUDAH,1)) | K5: =IF(Z5=1,COUNTIFS($B$2:$B$254,B5,$AA$2:$AA$254,">"&AA5)+1,"—") | L5: 1 | M5: Rating Kebiasaan Data di Kantor | N5: Relate | O5: “Rating kebiasaan data di kantor. Jujur, ya.” | P5: 1/10, 2/10, 3/10, 0/10 → papan disapu bersih → kartu Nexus 10/10 → CTA | Q5: 0.7 | R5: =IF(Q5="","",1-Q5) | S5: =IF(Q5="","—",TEXT(1-Q5,"0%")&" edukasi · "&TEXT(Q5,"0%")&" meme") | T5: RoPA, DSR, Insiden | U5: — | V5: 51,4 dtk | W5: T03 / A19 (sudah dirender) | X5: Waktu dikuantisasi 12 fps, getar kecil per langkah, tekstur gabus dari hash. | Y5: Nilai = lelucon rating. | Z5: =IF(OR(E5="Bisa",E5="Berat"),1,0) | AA5: =IF(Z5=1,J5-ROW()/100000,"") | AB5: =B5&"|"&K5
A6: TY05 | B6: Tipografi | C6: Mesin tik (typewriter) | D6: Kertas krem; huruf diketik satu-satu, bunyi “ting” di ujung baris, salah ketik ditimpa XXX. | E6: Sudah | F6: TY05 | G6: 2 | H6: 7 | I6: 8 | J6: =IF(E6="Tidak cocok","",ROUND(H6*W_GAYA_WOW+I6*W_GAYA_MEREK+(11-2*G6)*W_GAYA_MUDAH,1)) | K6: =IF(Z6=1,COUNTIFS($B$2:$B$254,B6,$AA$2:$AA$254,">"&AA6)+1,"—") | L6: 1 | M6: Surat yang Hampir Dikirim DPO | N6: Relate | O6: “Dengan hormat, saya mengundurkan diri sebagai satu-satunya orang yang mengurus data pribadi di kantor ini.” | P6: Surat diketik → kalimat ditimpa XXX → diganti “…atau beri saya alat yang layak.” → antrean kerja & dasbor → CTA | Q6: 0.3 | R6: =IF(Q6="","",1-Q6) | S6: =IF(Q6="","—",TEXT(1-Q6,"0%")&" edukasi · "&TEXT(Q6,"0%")&" meme") | T6: Dukungan PPDP (antrean kerja, dasbor) | U6: dashboard | V6: 20 dtk | W6: Baru (turunan M20) | X6: Huruf muncul per karakter (12–14 huruf/dtk), font Special Elite, kertas naik per baris; SFX key + ding. | Y6: Humor empati; jangan mengejek atasan. | Z6: =IF(OR(E6="Bisa",E6="Berat"),1,0) | AA6: =IF(Z6=1,J6-ROW()/100000,"") | AB6: =B6&"|"&K6
A7: TY06 | B7: Tipografi | C7: Terminal / command line | D7: Layar hitam, huruf monospace; perintah diketik, hasil muncul baris demi baris. | E7: Sudah | F7: TY06 | G7: 2 | H7: 7 | I7: 7 | J7: =IF(E7="Tidak cocok","",ROUND(H7*W_GAYA_WOW+I7*W_GAYA_MEREK+(11-2*G7)*W_GAYA_MUDAH,1)) | K7: =IF(Z7=1,COUNTIFS($B$2:$B$254,B7,$AA$2:$AA$254,">"&AA7)+1,"—") | L7: 1 | M7: cari --nama "rina" | N7: Anomali | O7: “Ketik nama satu pelanggan. Di berapa sistem datanya tersimpan?” | P7: Perintah cari diketik → hasil terus bertambah (CRM, email, CS, arsip) → “yang kamu tahu: 2” → Data Discovery menemukan & mengaitkan ke RoPA → CTA | Q7: 0.5 | R7: =IF(Q7="","",1-Q7) | S7: =IF(Q7="","—",TEXT(1-Q7,"0%")&" edukasi · "&TEXT(Q7,"0%")&" meme") | T7: Data Discovery (pencarian data satu subjek untuk DSR) | U7: — | V7: 20 dtk | W7: A38 / P15 | X7: Ketik per karakter + kursor blok berkedip; keluaran per baris; scanline tipis; SFX key/tick. | Y7: Jumlah sistem = ilustrasi. | Z7: =IF(OR(E7="Bisa",E7="Berat"),1,0) | AA7: =IF(Z7=1,J7-ROW()/100000,"") | AB7: =B7&"|"&K7
A8: TY07 | B8: Tipografi | C8: Editor kode (syntax highlight) | D8: Editor gelap dengan warna sintaks; baris kode ditulis, satu baris disorot. | E8: Sudah | F8: TY07 | G8: 2 | H8: 6 | I8: 7 | J8: =IF(E8="Tidak cocok","",ROUND(H8*W_GAYA_WOW+I8*W_GAYA_MEREK+(11-2*G8)*W_GAYA_MUDAH,1)) | K8: =IF(Z8=1,COUNTIFS($B$2:$B$254,B8,$AA$2:$AA$254,">"&AA8)+1,"—") | L8: 1 | M8: Satu Baris yang Sering Dilupakan | N8: Logika dipatahkan | O8: “Tombol ‘Setuju’ itu satu baris kode. Buktinya ada di baris mana?” | P8: onClick=setuju() diketik → komentar “// lalu buktinya?” → baris API persetujuan + webhook → log persetujuan tampil → CTA | Q8: 0.5 | R8: =IF(Q8="","",1-Q8) | S8: =IF(Q8="","—",TEXT(1-Q8,"0%")&" edukasi · "&TEXT(Q8,"0%")&" meme") | T8: Consent (API, webhook, log bukti) | U8: consent-detail | V8: 15 dtk | W8: M08 (sudut developer) | X8: Span berwarna per token, ketik per karakter, nomor baris, sorot baris + komentar muncul. | Y8: Kode = ilustrasi, bukan dokumentasi API. | Z8: =IF(OR(E8="Bisa",E8="Berat"),1,0) | AA8: =IF(Z8=1,J8-ROW()/100000,"") | AB8: =B8&"|"&K8
A9: TY08 | B9: Tipografi | C9: Text mask (layar di dalam huruf) | D9: Huruf raksasa memenuhi layar; layar aplikasi asli terlihat di dalam badan huruf. | E9: Sudah | F9: TY08 | G9: 2 | H9: 8 | I9: 9 | J9: =IF(E9="Tidak cocok","",ROUND(H9*W_GAYA_WOW+I9*W_GAYA_MEREK+(11-2*G9)*W_GAYA_MUDAH,1)) | K9: =IF(Z9=1,COUNTIFS($B$2:$B$254,B9,$AA$2:$AA$254,">"&AA9)+1,"—") | L9: 1 | M9: Ada Apa di Dalam Empat Huruf Ini? | N9: Anomali | O9: “RoPA. Empat huruf. Isinya: semua yang kantormu lakukan terhadap data pribadi.” | P9: RoPA raksasa → masuk ke huruf O → register RoPA asli → DPIA & DSR dengan cara sama → CTA | Q9: 0.2 | R9: =IF(Q9="","",1-Q9) | S9: =IF(Q9="","—",TEXT(1-Q9,"0%")&" edukasi · "&TEXT(Q9,"0%")&" meme") | T9: RoPA, DPIA, DSR | U9: ropa-list-baru, dpia-risiko, dsr-detail | V9: 20 dtk | W9: Baru (turunan M04) | X9: background-clip: text dengan screenshot sebagai latar; kamera mendekat sampai huruf jadi jendela. | Z9: =IF(OR(E9="Bisa",E9="Berat"),1,0) | AA9: =IF(Z9=1,J9-ROW()/100000,"") | AB9: =B9&"|"&K9
A10: TY09 | B10: Tipografi | C10: Liquid / huruf meleleh | D10: Huruf tebal meleleh, menetes, dan bergelombang seperti lilin. | E10: Sudah | F10: TY09 | G10: 3 | H10: 8 | I10: 7 | J10: =IF(E10="Tidak cocok","",ROUND(H10*W_GAYA_WOW+I10*W_GAYA_MEREK+(11-2*G10)*W_GAYA_MUDAH,1)) | K10: =IF(Z10=1,COUNTIFS($B$2:$B$254,B10,$AA$2:$AA$254,">"&AA10)+1,"—") | L10: 1 | M10: 72 Jam yang Meleleh | N10: Relate | O10: “72 jam itu cepat. Apalagi kalau dihitung manual.” | P10: Angka 72 JAM utuh → meleleh saat email bolak-balik → membeku jadi pil tenggat otomatis → CTA | Q10: 0.5 | R10: =IF(Q10="","",1-Q10) | S10: =IF(Q10="","—",TEXT(1-Q10,"0%")&" edukasi · "&TEXT(Q10,"0%")&" meme") | T10: DSR (tenggat otomatis 72 jam) | U10: dsr-detail | V10: 15 dtk | W10: M07 / P06 | X10: Filter SVG feTurbulence + feDisplacementMap dengan skala naik; tetesan dari elemen goo. | Z10: =IF(OR(E10="Bisa",E10="Berat"),1,0) | AA10: =IF(Z10=1,J10-ROW()/100000,"") | AB10: =B10&"|"&K10
A11: TY10 | B11: Tipografi | C11: Glitch / RGB split | D11: Huruf pecah jadi kanal merah-hijau-biru, bergeser, berkedip seperti sinyal rusak. | E11: Sudah | F11: TY10 | G11: 2 | H11: 7 | I11: 7 | J11: =IF(E11="Tidak cocok","",ROUND(H11*W_GAYA_WOW+I11*W_GAYA_MEREK+(11-2*G11)*W_GAYA_MUDAH,1)) | K11: =IF(Z11=1,COUNTIFS($B$2:$B$254,B11,$AA$2:$AA$254,">"&AA11)+1,"—") | L11: 1 | M11: 03.00 | N11: Anomali | O11: “Jam 03.00. Tulisan ini muncul di layar: dugaan kebocoran data.” | P11: Teks glitch → penghitung 3×24 jam mulai → daftar periksa penahanan muncul rapi (glitch hilang) → CTA | Q11: 0.5 | R11: =IF(Q11="","",1-Q11) | S11: =IF(Q11="","—",TEXT(1-Q11,"0%")&" edukasi · "&TEXT(Q11,"0%")&" meme") | T11: Manajemen Insiden | U11: breach-detail | V11: 15 dtk | W11: M11 / P03 | X11: Tiga salinan teks berwarna dengan offset dari hash per frame; potongan clip-path deterministik. | Z11: =IF(OR(E11="Bisa",E11="Berat"),1,0) | AA11: =IF(Z11=1,J11-ROW()/100000,"") | AB11: =B11&"|"&K11
A12: TY11 | B12: Tipografi | C12: Font variabel “bernapas” | D12: Satu kata menebal, melebar, lalu menipis mengikuti emosi kalimat. | E12: Sudah | F12: TY11 | G12: 2 | H12: 7 | I12: 8 | J12: =IF(E12="Tidak cocok","",ROUND(H12*W_GAYA_WOW+I12*W_GAYA_MEREK+(11-2*G12)*W_GAYA_MUDAH,1)) | K12: =IF(Z12=1,COUNTIFS($B$2:$B$254,B12,$AA$2:$AA$254,">"&AA12)+1,"—") | L12: 1 | M12: Minggu Depan Ya | N12: Relate | O12: “Begini rasanya saat auditor bilang: ‘minggu depan ya’.” | P12: Kata AUDIT tipis → makin tebal & sesak tiap hari → satu klik ekspor laporan kepatuhan → kata kembali lega → CTA | Q12: 0.3 | R12: =IF(Q12="","",1-Q12) | S12: =IF(Q12="","—",TEXT(1-Q12,"0%")&" edukasi · "&TEXT(Q12,"0%")&" meme") | T12: Dasbor kepatuhan, GAP Assessment | U12: dashboard, gap-hasil | V12: 15 dtk | W12: Baru (turunan M01) | X12: Font variabel (Archivo wght 100–900, wdth 62–125) dianimasikan per frame dari waktu. | Z12: =IF(OR(E12="Bisa",E12="Berat"),1,0) | AA12: =IF(Z12=1,J12-ROW()/100000,"") | AB12: =B12&"|"&K12
A13: TY12 | B13: Tipografi | C13: Elastis (huruf karet) | D13: Huruf ditarik memanjang seperti karet lalu memantul kembali. | E13: Sudah | F13: TY12 | G13: 2 | H13: 6 | I13: 7 | J13: =IF(E13="Tidak cocok","",ROUND(H13*W_GAYA_WOW+I13*W_GAYA_MEREK+(11-2*G13)*W_GAYA_MUDAH,1)) | K13: =IF(Z13=1,COUNTIFS($B$2:$B$254,B13,$AA$2:$AA$254,">"&AA13)+1,"—") | L13: 1 | M13: Yang Tidak Bisa Ditarik | N13: Logika dipatahkan | O13: “Tenggat proyek bisa ditarik-tarik. 3×24 jam tidak.” | P13: Kata TENGGAT ditarik berkali-kali → kata 3×24 JAM tidak bergerak → penghitung mundur insiden → CTA | Q13: 0.5 | R13: =IF(Q13="","",1-Q13) | S13: =IF(Q13="","—",TEXT(1-Q13,"0%")&" edukasi · "&TEXT(Q13,"0%")&" meme") | T13: Manajemen Insiden (penghitung mundur 3×24 jam) | U13: breach-detail | V13: 10 dtk | W13: P30 (varian) | X13: scaleX/scaleY dengan easing elastis, titik tumpu di sisi huruf. | Z13: =IF(OR(E13="Bisa",E13="Berat"),1,0) | AA13: =IF(Z13=1,J13-ROW()/100000,"") | AB13: =B13&"|"&K13
A14: TY13 | B14: Tipografi | C14: Marquee brutalist (teks berjalan bertumpuk) | D14: Baris-baris teks raksasa berjalan berlawanan arah, memenuhi layar. | E14: Sudah | F14: TY13 | G14: 1 | H14: 7 | I14: 7 | J14: =IF(E14="Tidak cocok","",ROUND(H14*W_GAYA_WOW+I14*W_GAYA_MEREK+(11-2*G14)*W_GAYA_MUDAH,1)) | K14: =IF(Z14=1,COUNTIFS($B$2:$B$254,B14,$AA$2:$AA$254,">"&AA14)+1,"—") | L14: 1 | M14: Yang Mana Punyamu? | N14: Anomali | O14: “Semua tulisan ini kewajiban. Yang mana yang sudah kamu kerjakan?” | P14: Pita kewajiban berjalan (catat pemrosesan · nilai risiko · jawab permohonan · lapor insiden) → berhenti & dicentang satu-satu → CTA | Q14: 0.5 | R14: =IF(Q14="","",1-Q14) | S14: =IF(Q14="","—",TEXT(1-Q14,"0%")&" edukasi · "&TEXT(Q14,"0%")&" meme") | T14: Platform, Paparan Sanksi | U14: — | V14: 15 dtk | W14: Baru | X14: Beberapa pita teks translateX berkecepatan beda; satu pita berhenti dan disorot. | Z14: =IF(OR(E14="Bisa",E14="Berat"),1,0) | AA14: =IF(Z14=1,J14-ROW()/100000,"") | AB14: =B14&"|"&K14
A15: TY14 | B15: Tipografi | C15: Papan LED berjalan | D15: Papan LED titik-titik merah/kuning seperti di depan toko; teks berjalan. | E15: Sudah | F15: TY14 | G15: 3 | H15: 8 | I15: 7 | J15: =IF(E15="Tidak cocok","",ROUND(H15*W_GAYA_WOW+I15*W_GAYA_MEREK+(11-2*G15)*W_GAYA_MUDAH,1)) | K15: =IF(Z15=1,COUNTIFS($B$2:$B$254,B15,$AA$2:$AA$254,">"&AA15)+1,"—") | L15: 1 | M15: Buka 24 Jam | N15: Relate | O15: “Kalau permohonan hak subjek data punya papan LED: BUKA 24 JAM.” | P15: Papan LED: “TERIMA PERMOHONAN HAPUS DATA” → “TENGGAT 72 JAM” menghitung → formulir DSR asli → CTA | Q15: 0.5 | R15: =IF(Q15="","",1-Q15) | S15: =IF(Q15="","—",TEXT(1-Q15,"0%")&" edukasi · "&TEXT(Q15,"0%")&" meme") | T15: DSR (formulir tersemat, tenggat 72 jam) | U15: dsr-form | V15: 15 dtk | W15: M07 (varian lokal) | X15: Kisi titik (canvas) menyala sesuai bitmap huruf, bergeser per kolom; pendar lembut. | Z15: =IF(OR(E15="Bisa",E15="Berat"),1,0) | AA15: =IF(Z15=1,J15-ROW()/100000,"") | AB15: =B15&"|"&K15
A16: TY15 | B16: Tipografi | C16: Angka digital / odometer | D16: Angka tujuh-segmen atau odometer yang terus berputar. | E16: Sudah | F16: TY15 | G16: 2 | H16: 6 | I16: 8 | J16: =IF(E16="Tidak cocok","",ROUND(H16*W_GAYA_WOW+I16*W_GAYA_MEREK+(11-2*G16)*W_GAYA_MUDAH,1)) | K16: =IF(Z16=1,COUNTIFS($B$2:$B$254,B16,$AA$2:$AA$254,">"&AA16)+1,"—") | L16: 1 | M16: Angka yang Mulai Berjalan | N16: Anomali | O16: “Angka ini mulai berjalan begitu insiden dicatat.” | P16: 72:00:00 mulai turun → tugas fase 1 tercentang satu-satu → templat pemberitahuan → CTA | Q16: 0.3 | R16: =IF(Q16="","",1-Q16) | S16: =IF(Q16="","—",TEXT(1-Q16,"0%")&" edukasi · "&TEXT(Q16,"0%")&" meme") | T16: Manajemen Insiden | U16: breach-fase, breach-aksi | V16: 15 dtk | W16: P30 | X16: Digit bergulir vertikal (translateY) dari nilai waktu; segmen menyala lewat kelas. | Z16: =IF(OR(E16="Bisa",E16="Berat"),1,0) | AA16: =IF(Z16=1,J16-ROW()/100000,"") | AB16: =B16&"|"&K16
A17: TY16 | B17: Tipografi | C17: Karaoke / lyric video | D17: Lirik di layar; bola kecil memantul di atas kata yang sedang dinyanyikan. | E17: Sudah | F17: TY16 | G17: 2 | H17: 7 | I17: 6 | J17: =IF(E17="Tidak cocok","",ROUND(H17*W_GAYA_WOW+I17*W_GAYA_MEREK+(11-2*G17)*W_GAYA_MUDAH,1)) | K17: =IF(Z17=1,COUNTIFS($B$2:$B$254,B17,$AA$2:$AA$254,">"&AA17)+1,"—") | L17: 1 | M17: Lagu Wajib Rapat Kepatuhan | N17: Relate | O17: “Nyanyikan bersama: ‘Datanya di mana? Di cloud.’” | P17: Bait 1: “Di cloud” → bait 2: “Cloud-nya di negara mana?” (hening) → register transfer lintas negara → CTA | Q17: 0.7 | R17: =IF(Q17="","",1-Q17) | S17: =IF(Q17="","—",TEXT(1-Q17,"0%")&" edukasi · "&TEXT(Q17,"0%")&" meme") | T17: Transfer Data Lintas Negara (TIA) | U17: — | V17: 20 dtk | W17: M14 / A34 | X17: Sorot per kata dari timing VO; bola mengikuti parabola antar kata. | Y17: Melodi orisinal (synth), bukan lagu yang sudah ada. | Z17: =IF(OR(E17="Bisa",E17="Berat"),1,0) | AA17: =IF(Z17=1,J17-ROW()/100000,"") | AB17: =B17&"|"&K17
A18: TY17 | B18: Tipografi | C18: Satu kata per layar | D18: Satu kata besar di tengah, berganti cepat mengikuti suara. | E18: Sudah | F18: TY17 | G18: 1 | H18: 6 | I18: 8 | J18: =IF(E18="Tidak cocok","",ROUND(H18*W_GAYA_WOW+I18*W_GAYA_MEREK+(11-2*G18)*W_GAYA_MUDAH,1)) | K18: =IF(Z18=1,COUNTIFS($B$2:$B$254,B18,$AA$2:$AA$254,">"&AA18)+1,"—") | L18: 1 | M18: Patuh Bukan Perasaan | N18: Logika dipatahkan | O18: “Patuh. Bukan. Perasaan.” | P18: Tiga kata → “Ukur.” → skor GAP 81% asli → CTA Start Pre Check | Q18: 0.3 | R18: =IF(Q18="","",1-Q18) | S18: =IF(Q18="","—",TEXT(1-Q18,"0%")&" edukasi · "&TEXT(Q18,"0%")&" meme") | T18: GAP Assessment | U18: gap-hasil | V18: 5–10 dtk | W18: P01 | X18: Ganti kata tepat di waktu ucapan; huruf tengah diberi warna sebagai titik fokus. | Y18: Skor 81% = data demo di screenshot. | Z18: =IF(OR(E18="Bisa",E18="Berat"),1,0) | AA18: =IF(Z18=1,J18-ROW()/100000,"") | AB18: =B18&"|"&K18
A19: TY18 | B19: Tipografi | C19: Text scramble / decode | D19: Huruf berputar acak lalu “terkunci” satu per satu menjadi kata yang benar. | E19: Sudah | F19: TY18 | G19: 2 | H19: 8 | I19: 8 | J19: =IF(E19="Tidak cocok","",ROUND(H19*W_GAYA_WOW+I19*W_GAYA_MEREK+(11-2*G19)*W_GAYA_MUDAH,1)) | K19: =IF(Z19=1,COUNTIFS($B$2:$B$254,B19,$AA$2:$AA$254,">"&AA19)+1,"—") | L19: 1 | M19: kol_17 | N19: Anomali | O19: “Kolom bernama ‘kol_17’ ini ternyata berisi NIK.” | P19: Nama kolom acak → terurai jadi NIK, no. HP, email → ditandai data pribadi umum/spesifik → dikaitkan ke RoPA → CTA | Q19: 0.3 | R19: =IF(Q19="","",1-Q19) | S19: =IF(Q19="","—",TEXT(1-Q19,"0%")&" edukasi · "&TEXT(Q19,"0%")&" meme") | T19: Data Discovery (pemindaian kolom) | U19: — | V19: 15 dtk | W19: M15 / P15 | X19: Tiap posisi huruf mengacak dari hash sampai waktu kuncinya; warna berubah saat terkunci. | Y19: Nama kolom = ilustrasi. | Z19: =IF(OR(E19="Bisa",E19="Berat"),1,0) | AA19: =IF(Z19=1,J19-ROW()/100000,"") | AB19: =B19&"|"&K19
A20: TY19 | B20: Tipografi | C20: Redaksi (sensor hitam) | D20: Dokumen dengan balok hitam menutupi kata; balok bergeser membuka atau menutup. | E20: Sudah | F20: TY19 | G20: 1 | H20: 7 | I20: 8 | J20: =IF(E20="Tidak cocok","",ROUND(H20*W_GAYA_WOW+I20*W_GAYA_MEREK+(11-2*G20)*W_GAYA_MUDAH,1)) | K20: =IF(Z20=1,COUNTIFS($B$2:$B$254,B20,$AA$2:$AA$254,">"&AA20)+1,"—") | L20: 1 | M20: Siapa yang Terakhir Membuka? | N20: Anomali | O20: “Siapa yang terakhir membuka data ini? ████████.” | P20: Kalimat dengan nama tertutup balok → balok terbuka: peran + waktu → log audit manusia & AI → CTA | Q20: 0.3 | R20: =IF(Q20="","",1-Q20) | S20: =IF(Q20="","—",TEXT(1-Q20,"0%")&" edukasi · "&TEXT(Q20,"0%")&" meme") | T20: Log audit (platform) | U20: — | V20: 15 dtk | W20: A42 | X20: Balok scaleX di atas teks; urutan buka mengikuti VO. | Z20: =IF(OR(E20="Bisa",E20="Berat"),1,0) | AA20: =IF(Z20=1,J20-ROW()/100000,"") | AB20: =B20&"|"&K20
A21: TY20 | B21: Tipografi | C21: Stabilo pada pasal | D21: Teks pasal di kertas; stabilo kuning menyapu frasa penting. | E21: Sudah | F21: TY20 | G21: 1 | H21: 6 | I21: 9 | J21: =IF(E21="Tidak cocok","",ROUND(H21*W_GAYA_WOW+I21*W_GAYA_MEREK+(11-2*G21)*W_GAYA_MUDAH,1)) | K21: =IF(Z21=1,COUNTIFS($B$2:$B$254,B21,$AA$2:$AA$254,">"&AA21)+1,"—") | L21: 1 | M21: AI yang Tidak Mengarang Pasal | N21: Logika dipatahkan | O21: “AI terbaik untuk DPO bukan yang paling kreatif. Tapi yang tidak mengarang pasal.” | P21: Jawaban AI → bunyi pasal disorot stabilo: diambil dari knowledge base → hasil bisa disunting konsultan → CTA | Q21: 0.2 | R21: =IF(Q21="","",1-Q21) | S21: =IF(Q21="","—",TEXT(1-Q21,"0%")&" edukasi · "&TEXT(Q21,"0%")&" meme") | T21: Telaah Kebijakan, Priva | U21: ai-agent-chat, policy-review | V21: 20 dtk | W21: M19 / P18 / A35 | X21: Latar kuning scaleX di belakang frasa, tepi tidak rata (SVG), mengikuti kata VO. | Y21: Kutip pasal persis; cek ulang bunyinya. | Z21: =IF(OR(E21="Bisa",E21="Berat"),1,0) | AA21: =IF(Z21=1,J21-ROW()/100000,"") | AB21: =B21&"|"&K21
A22: TY21 | B22: Tipografi | C22: Coret & tulis ulang (koreksi editor) | D22: Naskah diketik, dicoret tinta merah, ditulis ulang di atasnya. | E22: Sudah | F22: TY21 | G22: 2 | H22: 7 | I22: 8 | J22: =IF(E22="Tidak cocok","",ROUND(H22*W_GAYA_WOW+I22*W_GAYA_MEREK+(11-2*G22)*W_GAYA_MUDAH,1)) | K22: =IF(Z22=1,COUNTIFS($B$2:$B$254,B22,$AA$2:$AA$254,">"&AA22)+1,"—") | L22: 1 | M22: Lebih Tua dari Undang-undangnya | N22: Anomali | O22: “Kebijakan privasi di situsmu mungkin lebih tua dari UU PDP.” | P22: Halaman kebijakan “diperbarui 2019” → coretan merah per bab → temuan & rekomendasi → CTA | Q22: 0.3 | R22: =IF(Q22="","",1-Q22) | S22: =IF(Q22="","—",TEXT(1-Q22,"0%")&" edukasi · "&TEXT(Q22,"0%")&" meme") | T22: Telaah Kebijakan (per bab) | U22: policy-review | V22: 20 dtk | W22: M16 | X22: Garis coret digambar (stroke), tanda sisip muncul, teks pengganti ditulis tangan. | Y22: Crop angka yang tampil rusak di screenshot. | Z22: =IF(OR(E22="Bisa",E22="Berat"),1,0) | AA22: =IF(Z22=1,J22-ROW()/100000,"") | AB22: =B22&"|"&K22
A23: TY22 | B23: Tipografi | C23: Isi titik-titik | D23: Kalimat dengan ruang kosong bergaris; jawaban muncul, dihapus, diganti. | E23: Sudah | F23: TY22 | G23: 1 | H23: 6 | I23: 8 | J23: =IF(E23="Tidak cocok","",ROUND(H23*W_GAYA_WOW+I23*W_GAYA_MEREK+(11-2*G23)*W_GAYA_MUDAH,1)) | K23: =IF(Z23=1,COUNTIFS($B$2:$B$254,B23,$AA$2:$AA$254,">"&AA23)+1,"—") | L23: 1 | M23: Isi Titik-titik Ini | N23: Reverse psychology | O23: “Jangan isi titik-titik ini kalau belum yakin: data pelanggan kami disimpan di ______.” | P23: Jawaban berubah-ubah (server? laptop? pihak ketiga?) → katalog sistem & sumber data → CTA | Q23: 0.3 | R23: =IF(Q23="","",1-Q23) | S23: =IF(Q23="","—",TEXT(1-Q23,"0%")&" edukasi · "&TEXT(Q23,"0%")&" meme") | T23: Data Discovery, RoPA | U23: — | V23: 15 dtk | W23: Baru (turunan M15) | X23: Garis bawah + teks jawaban ketik/hapus bergantian; tanda tanya bergoyang. | Z23: =IF(OR(E23="Bisa",E23="Berat"),1,0) | AA23: =IF(Z23=1,J23-ROW()/100000,"") | AB23: =B23&"|"&K23
A24: TY23 | B24: Tipografi | C24: Cari kata | D24: Kotak huruf acak; kata yang ditemukan dilingkari satu per satu. | E24: Sudah | F24: TY23 | G24: 2 | H24: 7 | I24: 7 | J24: =IF(E24="Tidak cocok","",ROUND(H24*W_GAYA_WOW+I24*W_GAYA_MEREK+(11-2*G24)*W_GAYA_MUDAH,1)) | K24: =IF(Z24=1,COUNTIFS($B$2:$B$254,B24,$AA$2:$AA$254,">"&AA24)+1,"—") | L24: 1 | M24: Cari 5 Kewajiban | N24: Relate | O24: “Cari 5 kewajiban UU PDP di kotak ini. Waktumu 10 detik.” | P24: Timer berjalan → RoPA, DPIA, DSR, CONSENT, INSIDEN dilingkari → “di Nexus tidak perlu dicari” → CTA | Q24: 0.5 | R24: =IF(Q24="","",1-Q24) | S24: =IF(Q24="","—",TEXT(1-Q24,"0%")&" edukasi · "&TEXT(Q24,"0%")&" meme") | T24: Platform | U24: — | V24: 15 dtk | W24: Baru | X24: Grid huruf; lingkaran kapsul digambar (stroke) di atas kata; penghitung waktu. | Y24: Mengundang komentar & share. | Z24: =IF(OR(E24="Bisa",E24="Berat"),1,0) | AA24: =IF(Z24=1,J24-ROW()/100000,"") | AB24: =B24&"|"&K24
A25: TY24 | B25: Tipografi | C25: Tuts keyboard | D25: Tuts keyboard besar ditekan satu per satu membentuk pesan. | E25: Sudah | F25: TY24 | G25: 2 | H25: 7 | I25: 8 | J25: =IF(E25="Tidak cocok","",ROUND(H25*W_GAYA_WOW+I25*W_GAYA_MEREK+(11-2*G25)*W_GAYA_MUDAH,1)) | K25: =IF(Z25=1,COUNTIFS($B$2:$B$254,B25,$AA$2:$AA$254,">"&AA25)+1,"—") | L25: 1 | M25: Ctrl + Z | N25: Logika dipatahkan | O25: “Semua bisa di-undo. Kecuali data yang sudah bocor.” | P25: Ctrl+Z ditekan berulang, tidak terjadi apa-apa → yang bisa: latihan sebelum kejadian → Fire Drill → CTA | Q25: 0.3 | R25: =IF(Q25="","",1-Q25) | S25: =IF(Q25="","—",TEXT(1-Q25,"0%")&" edukasi · "&TEXT(Q25,"0%")&" meme") | T25: Simulasi & Fire Drill, Insiden | U25: fire-drill-header | V25: 10 dtk | W25: M12 / P17 | X25: Kotak tuts 3D semu (bayangan), turun 6 px saat ditekan; SFX key. | Z25: =IF(OR(E25="Bisa",E25="Berat"),1,0) | AA25: =IF(Z25=1,J25-ROW()/100000,"") | AB25: =B25&"|"&K25
A26: TY25 | B26: Tipografi | C26: Entri kamus | D26: Halaman kamus: kata, cara baca, kelas kata, definisi, contoh kalimat. | E26: Sudah | F26: TY25 | G26: 1 | H26: 7 | I26: 8 | J26: =IF(E26="Tidak cocok","",ROUND(H26*W_GAYA_WOW+I26*W_GAYA_MEREK+(11-2*G26)*W_GAYA_MUDAH,1)) | K26: =IF(Z26=1,COUNTIFS($B$2:$B$254,B26,$AA$2:$AA$254,">"&AA26)+1,"—") | L26: 1 | M26: DPO (n.) | N26: Relate | O26: “DPO (n.): orang yang ditanya semua hal tentang data, termasuk yang bukan urusannya.” | P26: Arti 1, 2, 3 makin jujur → arti 4: “punya antrean kerja dan asisten AI” → CTA | Q26: 0.3 | R26: =IF(Q26="","",1-Q26) | S26: =IF(Q26="","—",TEXT(1-Q26,"0%")&" edukasi · "&TEXT(Q26,"0%")&" meme") | T26: Dukungan PPDP, Priva | U26: ai-agent-home | V26: 15 dtk | W26: A40 / A12 | X26: Tata letak serif; definisi muncul per baris; nomor arti bertambah. | Z26: =IF(OR(E26="Bisa",E26="Berat"),1,0) | AA26: =IF(Z26=1,J26-ROW()/100000,"") | AB26: =B26&"|"&K26
A27: TY26 | B27: Tipografi | C27: Angka raksasa (big number) | D27: Satu angka memenuhi layar; keterangan kecil di bawahnya. | E27: Sudah | F27: TY26 | G27: 1 | H27: 7 | I27: 9 | J27: =IF(E27="Tidak cocok","",ROUND(H27*W_GAYA_WOW+I27*W_GAYA_MEREK+(11-2*G27)*W_GAYA_MUDAH,1)) | K27: =IF(Z27=1,COUNTIFS($B$2:$B$254,B27,$AA$2:$AA$254,">"&AA27)+1,"—") | L27: 1 | M27: 2% | N27: Anomali | O27: “Angka kecil yang membuat CFO berdiri dari kursinya: 2%.” | P27: 2% raksasa → “dari pendapatan tahunan” → pemetaan pasal bersanksi → CTA konsultasi | Q27: 0.2 | R27: =IF(Q27="","",1-Q27) | S27: =IF(Q27="","—",TEXT(1-Q27,"0%")&" edukasi · "&TEXT(Q27,"0%")&" meme") | T27: Paparan Sanksi Administratif | U27: — | V27: 10 dtk | W27: P29 / A08 | X27: Angka fit-to-width, masuk dengan hentakan; hitungan naik. | Y27: UU PDP Pasal 57 ayat (3): paling tinggi 2%. | Z27: =IF(OR(E27="Bisa",E27="Berat"),1,0) | AA27: =IF(Z27=1,J27-ROW()/100000,"") | AB27: =B27&"|"&K27
A28: TY27 | B28: Tipografi | C28: Huruf 3D / isometrik | D28: Huruf berdiri seperti gedung dengan sisi dan bayangan. | E28: Sudah | F28: TY27 | G28: 3 | H28: 8 | I28: 7 | J28: =IF(E28="Tidak cocok","",ROUND(H28*W_GAYA_WOW+I28*W_GAYA_MEREK+(11-2*G28)*W_GAYA_MUDAH,1)) | K28: =IF(Z28=1,COUNTIFS($B$2:$B$254,B28,$AA$2:$AA$254,">"&AA28)+1,"—") | L28: 1 | M28: Kota PP 33 | N28: Anomali | O28: “Bangunan ini selesai 16 Januari 2027. Kantormu sudah punya kuncinya?” | P28: Huruf PP 33 dibangun lantai demi lantai → tanggal muncul → program siap PP 33 → CTA | Q28: 0.5 | R28: =IF(Q28="","",1-Q28) | S28: =IF(Q28="","—",TEXT(1-Q28,"0%")&" edukasi · "&TEXT(Q28,"0%")&" meme") | T28: Program siap PP 33, GAP | U28: — | V28: 15 dtk | W28: P04 / A23 | X28: Lapisan text-shadow bertumpuk atau CSS 3D; kamera orbit kecil. | Z28: =IF(OR(E28="Bisa",E28="Berat"),1,0) | AA28: =IF(Z28=1,J28-ROW()/100000,"") | AB28: =B28&"|"&K28
A29: TY28 | B29: Tipografi | C29: Bayangan panjang (long shadow) | D29: Huruf datar dengan bayangan diagonal yang memanjang. | E29: Sudah | F29: TY28 | G29: 1 | H29: 5 | I29: 7 | J29: =IF(E29="Tidak cocok","",ROUND(H29*W_GAYA_WOW+I29*W_GAYA_MEREK+(11-2*G29)*W_GAYA_MUDAH,1)) | K29: =IF(Z29=1,COUNTIFS($B$2:$B$254,B29,$AA$2:$AA$254,">"&AA29)+1,"—") | L29: 1 | M29: Bayangan Tenggat | N29: Anomali | O29: “Makin dekat tanggalnya, makin panjang bayangannya.” | P29: “16 JAN” → bayangan memanjang menutupi meja kerja → daftar langkah siap PP 33 → CTA | Q29: 0.5 | R29: =IF(Q29="","",1-Q29) | S29: =IF(Q29="","—",TEXT(1-Q29,"0%")&" edukasi · "&TEXT(Q29,"0%")&" meme") | T29: Program siap PP 33 | U29: — | V29: 10 dtk | W29: A23 | X29: Bayangan dari banyak lapis offset; panjang bayangan = fungsi waktu. | Z29: =IF(OR(E29="Bisa",E29="Berat"),1,0) | AA29: =IF(Z29=1,J29-ROW()/100000,"") | AB29: =B29&"|"&K29
A30: TY29 | B30: Tipografi | C30: Outline + gema | D30: Huruf garis tepi dengan salinan yang mengekor seperti gema. | E30: Sudah | F30: TY29 | G30: 2 | H30: 7 | I30: 7 | J30: =IF(E30="Tidak cocok","",ROUND(H30*W_GAYA_WOW+I30*W_GAYA_MEREK+(11-2*G30)*W_GAYA_MUDAH,1)) | K30: =IF(Z30=1,COUNTIFS($B$2:$B$254,B30,$AA$2:$AA$254,">"&AA30)+1,"—") | L30: 1 | M30: Satu Permintaan, Tujuh Gema | N30: Relate | O30: “Satu permintaan: ‘hapus data saya’. Tujuh sistem yang harus menjawab.” | P30: Kata HAPUS bergema ke 7 arah → Data Discovery menemukan lokasinya → DSR terlacak sampai selesai → CTA | Q30: 0.5 | R30: =IF(Q30="","",1-Q30) | S30: =IF(Q30="","—",TEXT(1-Q30,"0%")&" edukasi · "&TEXT(Q30,"0%")&" meme") | T30: DSR, Data Discovery | U30: dsr-detail | V30: 15 dtk | W30: A38 | X30: Salinan teks stroke-only dengan jeda waktu & opasitas menurun. | Y30: Angka 7 = ilustrasi. | Z30: =IF(OR(E30="Bisa",E30="Berat"),1,0) | AA30: =IF(Z30=1,J30-ROW()/100000,"") | AB30: =B30&"|"&K30
A31: TY30 | B31: Tipografi | C31: Pola kata berulang | D31: Layar penuh kata yang sama seperti wallpaper; satu kata berbeda. | E31: Sudah | F31: TY30 | G31: 1 | H31: 6 | I31: 8 | J31: =IF(E31="Tidak cocok","",ROUND(H31*W_GAYA_WOW+I31*W_GAYA_MEREK+(11-2*G31)*W_GAYA_MUDAH,1)) | K31: =IF(Z31=1,COUNTIFS($B$2:$B$254,B31,$AA$2:$AA$254,">"&AA31)+1,"—") | L31: 1 | M31: 12 Definisi Patuh | N31: Anomali | O31: “1 grup usaha. 12 anak perusahaan. 12 definisi ‘patuh’.” | P31: Kata PATUH ×12 dengan huruf berbeda-beda → diseragamkan → dasbor grup → CTA konsultasi enterprise | Q31: 0.3 | R31: =IF(Q31="","",1-Q31) | S31: =IF(Q31="","—",TEXT(1-Q31,"0%")&" edukasi · "&TEXT(Q31,"0%")&" meme") | T31: Holding (asesmen & dasbor grup) | U31: holding-header | V31: 15 dtk | W31: M21 / P25 | X31: Grid teks; satu sel berubah warna/kata; kamera mendekat ke sel itu. | Y31: Tanpa nama grup/perusahaan nyata. | Z31: =IF(OR(E31="Bisa",E31="Berat"),1,0) | AA31: =IF(Z31=1,J31-ROW()/100000,"") | AB31: =B31&"|"&K31
A32: TY31 | B32: Tipografi | C32: Teks di jalur / pusaran | D32: Kalimat mengalir mengikuti lengkungan, spiral, atau pusaran. | E32: Sudah | F32: TY31 | G32: 2 | H32: 7 | I32: 7 | J32: =IF(E32="Tidak cocok","",ROUND(H32*W_GAYA_WOW+I32*W_GAYA_MEREK+(11-2*G32)*W_GAYA_MUDAH,1)) | K32: =IF(Z32=1,COUNTIFS($B$2:$B$254,B32,$AA$2:$AA$254,">"&AA32)+1,"—") | L32: 1 | M32: Ke Mana Perginya? | N32: Anomali | O32: “Ke mana perginya data setelah tombol ‘Kirim’ ditekan?” | P32: Kata nama–email–NIK berputar masuk pusaran → keluar sebagai baris RoPA: tujuan, penerima, retensi → CTA | Q32: 0.5 | R32: =IF(Q32="","",1-Q32) | S32: =IF(Q32="","—",TEXT(1-Q32,"0%")&" edukasi · "&TEXT(Q32,"0%")&" meme") | T32: RoPA | U32: ropa-tersimpan | V32: 15 dtk | W32: Baru (turunan M04) | X32: SVG textPath dengan startOffset dianimasikan; spiral mengecil ke tengah. | Z32: =IF(OR(E32="Bisa",E32="Berat"),1,0) | AA32: =IF(Z32=1,J32-ROW()/100000,"") | AB32: =B32&"|"&K32
A33: TY32 | B33: Tipografi | C33: Huruf berjatuhan | D33: Huruf lepas dari kalimat, jatuh, memantul, dan menumpuk di bawah. | E33: Sudah | F33: TY32 | G33: 3 | H33: 8 | I33: 6 | J33: =IF(E33="Tidak cocok","",ROUND(H33*W_GAYA_WOW+I33*W_GAYA_MEREK+(11-2*G33)*W_GAYA_MUDAH,1)) | K33: =IF(Z33=1,COUNTIFS($B$2:$B$254,B33,$AA$2:$AA$254,">"&AA33)+1,"—") | L33: 1 | M33: 40 Halaman | N33: Relate | O33: “Tidak ada yang membaca kebijakan privasi 40 halaman. Termasuk yang menulisnya.” | P33: Paragraf runtuh jadi tumpukan huruf → tersusun ulang jadi temuan per bab → CTA | Q33: 0.7 | R33: =IF(Q33="","",1-Q33) | S33: =IF(Q33="","—",TEXT(1-Q33,"0%")&" edukasi · "&TEXT(Q33,"0%")&" meme") | T33: Telaah Kebijakan | U33: policy-review | V33: 15 dtk | W33: M16 (varian) | X33: Lintasan jatuh dihitung dari rumus (tanpa simulasi acak); rotasi dari hash. | Y33: “40 halaman” = ilustrasi. | Z33: =IF(OR(E33="Bisa",E33="Berat"),1,0) | AA33: =IF(Z33=1,J33-ROW()/100000,"") | AB33: =B33&"|"&K33
A34: TY33 | B34: Tipografi | C34: Anagram (huruf bertukar tempat) | D34: Huruf-huruf sebuah kata bertukar tempat membentuk kata lain. | E34: Sudah | F34: TY33 | G34: 1 | H34: 9 | I34: 9 | J34: =IF(E34="Tidak cocok","",ROUND(H34*W_GAYA_WOW+I34*W_GAYA_MEREK+(11-2*G34)*W_GAYA_MUDAH,1)) | K34: =IF(Z34=1,COUNTIFS($B$2:$B$254,B34,$AA$2:$AA$254,">"&AA34)+1,"—") | L34: 1 | M34: NAMA ↔ AMAN | N34: Anomali | O34: “NAMA dan AMAN tersusun dari empat huruf yang sama.” | P34: NAMA → huruf bertukar → AMAN → “bedanya cuma di cara mengaturnya” → RoPA & log bukti → CTA | Q34: 0.1 | R34: =IF(Q34="","",1-Q34) | S34: =IF(Q34="","—",TEXT(1-Q34,"0%")&" edukasi · "&TEXT(Q34,"0%")&" meme") | T34: Platform, RoPA | U34: ropa-list-baru | V34: 10 dtk | W34: Baru | X34: Tiap huruf pindah posisi lewat lengkungan; jeda bertingkat. | Y34: Hook paling hemat: 4 huruf. | Z34: =IF(OR(E34="Bisa",E34="Berat"),1,0) | AA34: =IF(Z34=1,J34-ROW()/100000,"") | AB34: =B34&"|"&K34
A35: TY34 | B35: Tipografi | C35: Kaligram (kata membentuk gambar) | D35: Ratusan kata kecil tersusun membentuk gambar (gembok, perisai). | E35: Sudah | F35: TY34 | G35: 3 | H35: 8 | I35: 8 | J35: =IF(E35="Tidak cocok","",ROUND(H35*W_GAYA_WOW+I35*W_GAYA_MEREK+(11-2*G35)*W_GAYA_MUDAH,1)) | K35: =IF(Z35=1,COUNTIFS($B$2:$B$254,B35,$AA$2:$AA$254,">"&AA35)+1,"—") | L35: 1 | M35: Gembok dari Kata-kata | N35: Anomali | O35: “Gembok ini tidak terbuat dari besi, tapi dari catatan.” | P35: Kata RoPA, DPIA, bukti, log, tenggat… berkumpul → membentuk gembok → logo → CTA | Q35: 0.3 | R35: =IF(Q35="","",1-Q35) | S35: =IF(Q35="","—",TEXT(1-Q35,"0%")&" edukasi · "&TEXT(Q35,"0%")&" meme") | T35: Platform | U35: — | V35: 10 dtk | W35: Baru (bumper) | X35: Kata ditempatkan di titik-titik siluet (dihitung sekali), muncul bergelombang. | Z35: =IF(OR(E35="Bisa",E35="Berat"),1,0) | AA35: =IF(Z35=1,J35-ROW()/100000,"") | AB35: =B35&"|"&K35
A36: TY35 | B36: Tipografi | C36: ASCII art | D36: Gambar dari karakter ketik (#, /, |) di layar terminal. | E36: Sudah | F36: TY35 | G36: 2 | H36: 7 | I36: 6 | J36: =IF(E36="Tidak cocok","",ROUND(H36*W_GAYA_WOW+I36*W_GAYA_MEREK+(11-2*G36)*W_GAYA_MUDAH,1)) | K36: =IF(Z36=1,COUNTIFS($B$2:$B$254,B36,$AA$2:$AA$254,">"&AA36)+1,"—") | L36: 1 | M36: README.md | N36: Reverse psychology | O36: “Jangan baca README ini kalau integrasimu sudah mencatat bukti persetujuan.” | P36: README ASCII → 3 langkah integrasi (sematkan, API, webhook) → gembok ASCII → CTA | Q36: 0.7 | R36: =IF(Q36="","",1-Q36) | S36: =IF(Q36="","—",TEXT(1-Q36,"0%")&" edukasi · "&TEXT(Q36,"0%")&" meme") | T36: Consent, DSR (API & webhook) | U36: consent-detail | V36: 15 dtk | W36: Baru (audiens developer) | X36: Blok <pre> monospace; baris muncul dari atas; karakter berganti membentuk gambar. | Z36: =IF(OR(E36="Bisa",E36="Berat"),1,0) | AA36: =IF(Z36=1,J36-ROW()/100000,"") | AB36: =B36&"|"&K36
A37: TY36 | B37: Tipografi | C37: Subtitle saja di layar hitam | D37: Layar hitam total; hanya subtitle dan suara (langkah kaki, pintu, ketukan). | E37: Sudah | F37: TY36 | G37: 1 | H37: 8 | I37: 8 | J37: =IF(E37="Tidak cocok","",ROUND(H37*W_GAYA_WOW+I37*W_GAYA_MEREK+(11-2*G37)*W_GAYA_MUDAH,1)) | K37: =IF(Z37=1,COUNTIFS($B$2:$B$254,B37,$AA$2:$AA$254,">"&AA37)+1,"—") | L37: 1 | M37: Selamat Pagi, Kami dari Tim Audit | N37: Anomali | O37: “[pintu diketuk] Selamat pagi, kami dari tim audit.” | P37: Dialog tanpa gambar → “[hening panjang]” → layar menyala: dasbor kepatuhan → CTA | Q37: 0.3 | R37: =IF(Q37="","",1-Q37) | S37: =IF(Q37="","—",TEXT(1-Q37,"0%")&" edukasi · "&TEXT(Q37,"0%")&" meme") | T37: Dasbor, GAP Assessment | U37: dashboard | V37: 15 dtk | W37: Baru (turunan A16) | X37: Teks subtitle + keterangan suara dalam kurung; desain suara jadi “gambar”. | Y37: Produksi paling ringan. | Z37: =IF(OR(E37="Bisa",E37="Berat"),1,0) | AA37: =IF(Z37=1,J37-ROW()/100000,"") | AB37: =B37&"|"&K37
A38: TY37 | B38: Tipografi | C38: Tulisan tangan (write-on) | D38: Kalimat ditulis tangan huruf demi huruf, seperti catatan di kertas. | E38: Sudah | F38: TY37 | G38: 2 | H38: 6 | I38: 8 | J38: =IF(E38="Tidak cocok","",ROUND(H38*W_GAYA_WOW+I38*W_GAYA_MEREK+(11-2*G38)*W_GAYA_MUDAH,1)) | K38: =IF(Z38=1,COUNTIFS($B$2:$B$254,B38,$AA$2:$AA$254,">"&AA38)+1,"—") | L38: 1 | M38: Catatan Kecil untuk Direksi | N38: Relate | O38: “Pak, laporannya 482 halaman. Ringkasannya satu layar.” | P38: Catatan ditulis di kertas tempel → ditempel di tumpukan laporan → dasbor satu layar → CTA | Q38: 0.3 | R38: =IF(Q38="","",1-Q38) | S38: =IF(Q38="","—",TEXT(1-Q38,"0%")&" edukasi · "&TEXT(Q38,"0%")&" meme") | T38: Dasbor kepatuhan | U38: dashboard | V38: 10 dtk | W38: P32 / M01 | X38: Font tulisan tangan + pembuka clip-path per huruf; ujung pena mengikuti. | Y38: “482 halaman” = ilustrasi. | Z38: =IF(OR(E38="Bisa",E38="Berat"),1,0) | AA38: =IF(Z38=1,J38-ROW()/100000,"") | AB38: =B38&"|"&K38
A39: TY38 | B39: Tipografi | C39: Kaligrafi kuas | D39: Satu kata digores kuas tinta tebal, dengan cipratan kecil. | E39: Sudah | F39: TY38 | G39: 3 | H39: 8 | I39: 7 | J39: =IF(E39="Tidak cocok","",ROUND(H39*W_GAYA_WOW+I39*W_GAYA_MEREK+(11-2*G39)*W_GAYA_MUDAH,1)) | K39: =IF(Z39=1,COUNTIFS($B$2:$B$254,B39,$AA$2:$AA$254,">"&AA39)+1,"—") | L39: 1 | M39: Satu Kata untuk 2027 | N39: Logika dipatahkan | O39: “Resolusi 2027 kantor ini cukup satu kata.” | P39: Kertas kosong → goresan kuas: RAPI → daftar langkah siap PP 33 → CTA | Q39: 0.5 | R39: =IF(Q39="","",1-Q39) | S39: =IF(Q39="","—",TEXT(1-Q39,"0%")&" edukasi · "&TEXT(Q39,"0%")&" meme") | T39: GAP, program siap PP 33 | U39: — | V39: 10 dtk | W39: A24 | X39: Masker sapuan (clip-path/mask) membuka teks; tekstur tinta dari turbulence. | Z39: =IF(OR(E39="Bisa",E39="Berat"),1,0) | AA39: =IF(Z39=1,J39-ROW()/100000,"") | AB39: =B39&"|"&K39
A40: TY39 | B40: Tipografi | C40: Stensil / cat semprot | D40: Huruf stensil disemprot ke dinding; cat meluber di tepi. | E40: Sudah | F40: TY39 | G40: 2 | H40: 7 | I40: 5 | J40: =IF(E40="Tidak cocok","",ROUND(H40*W_GAYA_WOW+I40*W_GAYA_MEREK+(11-2*G40)*W_GAYA_MUDAH,1)) | K40: =IF(Z40=1,COUNTIFS($B$2:$B$254,B40,$AA$2:$AA$254,">"&AA40)+1,"—") | L40: 1 | M40: Dilarang Patuh Setengah-setengah | N40: Reverse psychology | O40: “DILARANG PATUH SETENGAH-SETENGAH.” | P40: Tulisan disemprot → panah ke daftar “setengah” (RoPA ada, bukti tidak) → GAP Assessment → CTA | Q40: 0.8 | R40: =IF(Q40="","",1-Q40) | S40: =IF(Q40="","—",TEXT(1-Q40,"0%")&" edukasi · "&TEXT(Q40,"0%")&" meme") | T40: GAP Assessment | U40: gap-rekomendasi | V40: 10 dtk | W40: Baru | X40: Font stensil + tekstur bintik (canvas hash) + garis lelehan cat turun. | Y40: Nada keras; cocok organik, bukan iklan korporat. | Z40: =IF(OR(E40="Bisa",E40="Berat"),1,0) | AA40: =IF(Z40=1,J40-ROW()/100000,"") | AB40: =B40&"|"&K40
...

Sheet Hook Frasa Viral
A1: Hook frasa viral (termasuk frasa politik): pemancing perhatian, versi aman
A2: Frasa dipakai sebagai PEMANCING di 0–3 detik pertama, lalu video kembali ke pesan produk. Yang dipakai hanya frasanya (teks + suara tim); wajah, suara asli, nama, klip video, dan gambar meme tokoh TIDAK dipakai. Konteks tiap frasa cepat berubah: cek ulang sebelum tayang.
A4: Aturan pakai
A5: 1. Yang boleh: FRASA-nya saja, ditulis sebagai teks dan diucapkan tim/TTS dengan gaya sendiri.
A6: 2. Yang tidak dipakai di iklan: wajah, foto, video, suara asli, nama, atau tiruan suara/logat tokoh mana pun.
A7: 3. Dasar: UU Hak Cipta No. 28/2014 Pasal 12: potret orang untuk reklame/iklan komersial wajib izin tertulis dari orangnya (ancaman denda sampai Rp500 juta).
